Workbook
Name CEPCI_ref: [1]Calculations!$C$28
Name CEPCI2014: [1]Calculations!$C$22
Name CEPCI2015: [1]Calculations!$C$23
Name DE2014_: [1]Calculations!$C$8

Sheet Data_base_case
A1: Red: Don't change the name without changing the Julia code | F1: Used (1 or 0) | G1: Unit tag | H1: Yearly demand (kg fuel) | I1: Produced from | J1: El balance | K1: Heat balance | L1: H2 balance | M1: CSP balance | N1: Max Capacity | O1: Fuel production rate (kg output/kg input) | P1: Heat generated (kWh/output) | Q1: Load min (% of max capacity) | R1: Ramp up (% of capacity /h) | S1: Ramp down (% of capacity /h) | T1: Electrical consumption (kWh/output) | U1: Investment (EUR/Capacity installed) | V1: Fixed cost (EUR/Capacity installed/y) | W1: Variable cost (EUR/output) | X1: Fuel selling price (EUR/output) | Y1: Fuel buying price (EUR/output) | Z1: Annuity factor
B2: Subsets | C2: Subsets_2 | D2: Type of units | E2: Parameters--> | F2: =F1 -> Used (1 or 0) | G2: =G1 -> Unit tag | H2: =H1 -> Yearly demand (kg fuel) | I2: =I1 -> Produced from | J2: =J1 -> El balance | K2: =K1 -> Heat balance | L2: =L1 -> H2 balance | M2: =M1 -> CSP balance | N2: Max Capacity | O2: =O1 -> Fuel production rate (kg output/kg input) | P2: =P1 -> Heat generated (kWh/output) | Q2: =Q1 -> Load min (% of max capacity) | R2: =R1 -> Ramp up (% of capacity /h) | S2: =S1 -> Ramp down (% of capacity /h) | T2: =T1 -> Electrical consumption (kWh/output) | U2: =U1 -> Investment (EUR/Capacity installed) | V2: =V1 -> Fixed cost (EUR/Capacity installed/y) | ... Z2: =Z1 -> Annuity factor
E3: Year--> | F3: 2020 | G3: 2020 | H3: 2020 | I3: 2020 | J3: 2020 | K3: 2020 | L3: 2020 | M3: 2020 | N3: 2020 | O3: 2020 | P3: 2020 | Q3: 2020 | R3: 2020 | S3: 2020 | T3: 2020 | U3: 2020 | V3: 2020 | W3: 2020 | X3: 2020 | Y3: 2020 | Z3: 2020
F4: =F2&F3 -> Used (1 or 0)2020 | G4: =G2&G3 -> Unit tag2020 | H4: =H2&H3 -> Yearly demand (kg fuel)2020 | I4: =I2&I3 -> Produced from2020 | J4: =J2&J3 -> El balance2020 | K4: =K2&K3 -> Heat balance2020 | L4: =L2&L3 -> H2 balance2020 | M4: =M2&M3 -> CSP balance2020 | ... Z4: =Z2&Z3 -> Annuity factor2020
E5: Line/Column index | F5: =COLUMN(F2)-COLUMN($E$5) -> 1 | G5: =COLUMN(G2)-COLUMN($E$5) -> 2 | H5: =COLUMN(H2)-COLUMN($E$5) -> 3 | I5: =COLUMN(I2)-COLUMN($E$5) -> 4 | J5: =COLUMN(J2)-COLUMN($E$5) -> 5 | K5: =COLUMN(K2)-COLUMN($E$5) -> 6 | L5: =COLUMN(L2)-COLUMN($E$5) -> 7 | M5: =COLUMN(M2)-COLUMN($E$5) -> 8 | ... Z5: =COLUMN(Z2)-COLUMN($E$5) -> 21
A6: Non-electrical | B6: Product | C6: Min_demand_MainFuel | D6: NH3 plant + ASU - AEC | E6: =ROW(D6)-ROW($E$5) -> 1 | F6: 1 | G6: NH3-AEC | H6: 1000000000 | I6: =B11 -> Reactant3 | J6: 0 | K6: 1 | L6: 0 | M6: 0 | N6: 20000 | O6: 5.5533333 | P6: 0 | Q6: 0.4 | R6: 0.2 | S6: 0.2 | T6: 0.38 | U6: 4192 | V6: 436 | W6: 0 | X6: 0 | Y6: 0 | Z6: 0.085810517
B7: Product | C7: Min_demand_MainFuel | D7: NH3 plant + ASU - SOEC | E7: =ROW(D7)-ROW($E$5) -> 2 | F7: 1 | G7: NH3-SOEC | H7: =H6 -> 1000000000 | I7: =B11 -> Reactant3 | J7: 0 | K7: 1 | L7: 0 | M7: 0 | N7: 20000 | O7: 5.5533333 | P7: 0 | Q7: 0.4 | R7: 0.2 | S7: 0.2 | T7: 0.83 | U7: 4192 | V7: 828 | W7: 0 | X7: 0 | Y7: 0 | Z7: 0.085810517
B8: Reactant1 | C8: NoSubset | D8: Desalination plant | E8: =ROW(D8)-ROW($E$5) -> 3 | F8: 1 | G8: H2O | H8: 0 | I8: - | J8: 0 | K8: 0 | L8: 0 | M8: 0 | N8: 400000 | O8: 0 | P8: 0 | Q8: 0 | R8: 1 | S8: 1 | T8: 0.004 | U8: 26.145192 | V8: 0 | W8: 0.00025895169 | X8: 0 | Y8: 0 | Z8: 0.094392926
B9: Product/Reactant2 | C9: NoSubset | D9: Electrolyser AEC | E9: =ROW(D9)-ROW($E$5) -> 4 | F9: 1 | G9: H2_from_AEC | H9: 0 | I9: =B8 -> Reactant1 | J9: 0 | K9: 1 | L9: 1 | M9: 0 | N9: 20000 | O9: 0.067 | P9: 7.07 | Q9: 0 | R9: 1 | S9: 1 | T9: 51.5 | U9: 46863 | V9: =2%*U9 -> 937.26 | W9: 0 | X9: 0 | Y9: 0 | Z9: 0.085810517
B10: Product/Reactant2 | C10: NoSubset | D10: Electrolyser SOEC | E10: =ROW(D10)-ROW($E$5) -> 5 | F10: 1 | G10: H2_from_SOEC | H10: 0 | I10: =B8 -> Reactant1 | J10: 0 | K10: 1 | L10: 1 | M10: 0 | N10: 20000 | O10: 0.067 | P10: 0 | Q10: 0 | R10: 1 | S10: 1 | T10: 37.9 | U10: 131493 | V10: 3945 | W10: 0 | X10: 0 | Y10: 0 | Z10: 0.085810517
B11: Reactant3 | C11: NoSubset | D11: H2 pipeline to NH3 plant | E11: =ROW(D11)-ROW($E$5) -> 6 | F11: 1 | G11: H2_pipeline_to_NH3_plant | H11: 0 | I11: - | J11: 0 | K11: 0 | L11: -1 | M11: 0 | N11: 20000 | O11: 0 | P11: 0 | Q11: 0 | R11: 1 | S11: 1 | T11: 0 | U11: 0 | V11: 0 | W11: 0 | X11: 0 | Y11: 0 | Z11: 0
B12: Product | C12: O2_sell | D12: Sale of oxygen | E12: =ROW(D12)-ROW($E$5) -> 7 | F12: 1 | G12: O2 | H12: 0 | I12: =B9 -> Product/Reactant2 | J12: 0 | K12: 0 | L12: 0 | M12: 0 | N12: 180000 | O12: 7.76 | P12: 0 | Q12: 0 | R12: 1 | S12: 1 | T12: 0 | U12: 0 | V12: 0 | W12: 0 | X12: 0.05 | Y12: 0 | Z12: 0
B13: Heat_in | C13: NoSubset | D13: Heat from district heating | E13: =ROW(D13)-ROW($E$5) -> 8 | F13: 1 | G13: Heat_import | H13: 0 | I13: - | J13: 0 | K13: 1 | L13: 0 | M13: 0 | N13: 2000000 | O13: 0 | P13: 0 | Q13: 0 | R13: 1 | S13: 1 | T13: 0 | U13: 0 | V13: 0 | W13: 0 | X13: 0 | Y13: 0 | Z13: 0
B14: Heat_out | C14: Heat_sell | D14: Heat sent to district heating | E14: =ROW(D14)-ROW($E$5) -> 9 | F14: 1 | G14: Heat_export | H14: 0 | I14: - | J14: 0 | K14: -1 | L14: 0 | M14: 0 | N14: 2000000 | O14: 0 | P14: 1 | Q14: 0 | R14: 1 | S14: 1 | T14: 0 | U14: 0 | V14: 0 | W14: 0 | X14: 0.023 | Y14: 0 | Z14: 0
B15: Stor_in | C15: NoSubset | D15: H2 pipes compressor | E15: =ROW(D15)-ROW($E$5) -> 10 | F15: 1 | G15: H2_to_pipe | H15: 0 | I15: - | J15: 0 | K15: 0 | L15: -1 | M15: 0 | N15: 20000 | O15: 0 | P15: 0 | Q15: 0 | R15: 1 | S15: 1 | T15: 0.94 | U15: 0 | V15: 0 | W15: 1e-05 | X15: 0 | Y15: 0 | Z15: 0.085810517
B16: Stor_out | C16: NoSubset | D16: H2 pipes valve | E16: =ROW(D16)-ROW($E$5) -> 11 | F16: 1 | G16: H2_from_pipe | H16: 0 | I16: - | J16: 0 | K16: 0 | L16: 1 | M16: 0 | N16: 20000 | O16: 0 | P16: 0 | Q16: 0 | R16: 1 | S16: 1 | T16: 0 | U16: 0 | V16: 0 | W16: 0 | X16: 0 | Y16: 0 | Z16: 0
B17: Tank | C17: NoSubset | D17: H2 buried pipes | E17: =ROW(D17)-ROW($E$5) -> 12 | F17: 1 | G17: H2_stored_pipe | H17: 0 | I17: - | J17: 0 | K17: 0 | L17: 0 | M17: 0 | N17: 20000000 | O17: 0 | P17: 0 | Q17: 0.09 | R17: 1 | S17: 1 | T17: 0 | U17: 460.75542 | V17: 0.99167601 | W17: 0 | X17: 0 | Y17: 0 | Z17: 0.07245985
B18: RPU_Solar_track | C18: NoSubset | D18: Solar tracking | E18: =ROW(D18)-ROW($E$5) -> 13 | F18: 1 | G18: Solar_tracking | H18: 0 | I18: - | J18: 1 | K18: 0 | L18: 0 | M18: 0 | N18: 2000000 | O18: 0 | P18: 0 | Q18: 0 | R18: 1 | S18: 1 | T18: 0 | U18: 717.386 | V18: =0.01*U18 -> 7.17386 | W18: 0 | X18: 0 | Y18: 0 | Z18: 0.0772
B19: RPU_CSP_ST50 | C19: NoSubset | D19: CSP Plant tower 50 MW | E19: =ROW(D19)-ROW($E$5) -> 14 | F19: 1 | G19: CSP_Tower_50 | H19: 0 | I19: - | J19: 0 | K19: 0 | L19: 0 | M19: 1 | N19: 2000000 | O19: 0 | P19: 0 | Q19: 0 | R19: 1 | S19: 1 | T19: 0 | U19: 3440.462 | V19: =59.5838298652489 -> 59.58383 | W19: =4.58337152809607/1000 -> 0.0045833715 | X19: 0 | Y19: 0 | Z19: 0.085810517
B20: RPU_CSP_ST100 | C20: NoSubset | D20: CSP Plant tower 100 MW | E20: =ROW(D20)-ROW($E$5) -> 15 | F20: 1 | G20: CSP_Tower_100 | H20: 0 | I20: - | J20: 0 | K20: 0 | L20: 0 | M20: 1 | N20: 2000000 | O20: 0 | P20: 0 | Q20: 0 | R20: 1 | S20: 1 | T20: 0 | U20: =3296.48913740948 -> 3296.4891 | V20: =59.5838298652489 -> 59.58383 | W20: =4.58337152809607/1000 -> 0.0045833715 | X20: 0 | Y20: 0 | Z20: 0.085810517
B21: RPU_CSP_PT50 | C21: NoSubset | D21: CSP Plant parabolic 50 MW | E21: =ROW(D21)-ROW($E$5) -> 16 | F21: 1 | G21: CSP_Parabolic_50 | H21: 0 | I21: - | J21: 0 | K21: 0 | L21: 0 | M21: 1 | N21: 2000000 | O21: 0 | P21: 0 | Q21: 0 | R21: 1 | S21: 1 | T21: 0 | U21: 3185.84 | V21: =59.5838298652489 -> 59.58383 | W21: =4.58337152809607/1000 -> 0.0045833715 | X21: 0 | Y21: 0 | Z21: 0.085810517
B22: RPU_CSP_PT100 | C22: NoSubset | D22: CSP Plant parabolic 100 MW | E22: =ROW(D22)-ROW($E$5) -> 17 | F22: 1 | G22: CSP_Parabolic_100 | H22: 0 | I22: - | J22: 0 | K22: 0 | L22: 0 | M22: 1 | N22: 2000000 | O22: 0 | P22: 0 | Q22: 0 | R22: 1 | S22: 1 | T22: 0 | U22: 2910.0376 | V22: =59.5838298652489 -> 59.58383 | W22: =4.58337152809607/1000 -> 0.0045833715 | X22: 0 | Y22: 0 | Z22: 0.085810517
B23: Stor_in | C23: NoSubset | D23: Charge TES | E23: =ROW(D23)-ROW($E$5) -> 18 | F23: 1 | G23: Charge_TES | H23: 0 | I23: - | J23: 0 | K23: 0 | L23: 0 | M23: -1 | N23: 2000000 | O23: 0 | P23: 0 | Q23: 0 | R23: 1 | S23: 1 | T23: 0 | U23: 0 | V23: 0 | W23: 0 | X23: 0 | Y23: 0 | Z23: 0
B24: Stor_out | C24: NoSubset | D24: Discharge TES | E24: =ROW(D24)-ROW($E$5) -> 19 | F24: 1 | G24: Discharge_TES | H24: 0 | I24: - | J24: 0 | K24: 0 | L24: 0 | M24: 1 | N24: 2000000 | O24: 0 | P24: 0 | Q24: 0 | R24: 1 | S24: 1 | T24: 0 | U24: 0 | V24: 0 | W24: 0 | X24: 0 | Y24: 0 | Z24: 0
B25: Tank | C25: NoSubset | D25: TES ST 50 MW | E25: =ROW(D25)-ROW($E$5) -> 20 | F25: 1 | G25: TES ST 50MW | H25: 0 | I25: - | J25: 0 | K25: 0 | L25: 0 | M25: 0 | N25: 2000000 | O25: 0 | P25: 0 | Q25: 0 | R25: 1 | S25: 1 | T25: 0 | U25: 38.227356 | V25: =0.0482193715280961 -> 0.048219372 | W25: 0 | X25: 0 | Y25: 0 | Z25: 0.085810517
B26: Tank | C26: NoSubset | D26: TES ST 100 MW | E26: =ROW(D26)-ROW($E$5) -> 21 | F26: 1 | G26: TES ST 100MW | H26: 0 | I26: - | J26: 0 | K26: 0 | L26: 0 | M26: 0 | N26: 2000000 | O26: 0 | P26: 0 | Q26: 0 | R26: 1 | S26: 1 | T26: 0 | U26: 36.627657 | V26: =0.0482193715280961 -> 0.048219372 | W26: 0 | X26: 0 | Y26: 0 | Z26: 0.085810517
B27: Tank | C27: NoSubset | D27: TES PT 50 MW | E27: =ROW(D27)-ROW($E$5) -> 22 | F27: 1 | G27: TES PT 50 MW | H27: 0 | I27: - | J27: 0 | K27: 0 | L27: 0 | M27: 0 | N27: 2000000 | O27: 0 | P27: 0 | Q27: 0 | R27: 1 | S27: 1 | T27: 0 | U27: 81.415911 | V27: =0.0482193715280961 -> 0.048219372 | W27: 0 | X27: 0 | Y27: 0 | Z27: 0.085810517
B28: Tank | C28: NoSubset | D28: TES PT 100 MW | E28: =ROW(D28)-ROW($E$5) -> 23 | F28: 1 | G28: TES PT 100MW | H28: 0 | I28: - | J28: 0 | K28: 0 | L28: 0 | M28: 0 | N28: 2000000 | O28: 0 | P28: 0 | Q28: 0 | R28: 1 | S28: 1 | T28: 0 | U28: 74.367627 | V28: =0.0482193715280961 -> 0.048219372 | W28: 0 | X28: 0 | Y28: 0 | Z28: 0.085810517
B29: NoSubset | C29: NoSubset | D29: CSP+TES | E29: =ROW(D29)-ROW($E$5) -> 24 | F29: 1 | G29: CSP + TES | H29: 0 | I29: - | J29: 1 | K29: 0 | L29: 0 | M29: -1 | N29: 2000000 | O29: 0 | P29: 0 | Q29: 0 | R29: 1 | S29: 1 | T29: 0 | U29: 0 | V29: 0 | W29: 0 | X29: 0 | Y29: 0 | Z29: 0
B30: RPU_ON_SP277_HH100 | C30: NoSubset | D30: ON-SP277-HH100 | E30: =ROW(D30)-ROW($E$5) -> 25 | F30: 1 | G30: SP277-HH100 | H30: 0 | I30: - | J30: 1 | K30: 0 | L30: 0 | M30: 0 | N30: 2000000 | O30: 0 | P30: 0 | Q30: 0 | R30: 1 | S30: 1 | T30: 0 | U30: 1250 | V30: =0.02*U30 -> 25 | W30: 0.001593 | X30: 0 | Y30: 0 | Z30: 0.0834
B31: RPU_ON_SP335_HH100 | C31: NoSubset | D31: ON-SP335-HH100 | E31: =ROW(D31)-ROW($E$5) -> 26 | F31: 1 | G31: SP335-HH100 | H31: 0 | I31: - | J31: 1 | K31: 0 | L31: 0 | M31: 0 | N31: 2000000 | O31: 0 | P31: 0 | Q31: 0 | R31: 1 | S31: 1 | T31: 0 | U31: 1140 | V31: =0.02*U31 -> 22.8 | W31: 0.001593 | X31: 0 | Y31: 0 | Z31: 0.0834
B32: RPU_OFF_1_SP316_HH150 | C32: NoSubset | D32: OFF-1-SP316-HH150 | E32: =ROW(D32)-ROW($E$5) -> 27 | F32: 1 | G32: SP316-HH150-v1 | H32: 0 | I32: - | J32: 1 | K32: 0 | L32: 0 | M32: 0 | N32: 2000000 | O32: 0 | P32: 0 | Q32: 0 | R32: 1 | S32: 1 | T32: 0 | U32: 4823 | V32: =U32*0.02 -> 96.46 | W32: 0.0031 | X32: 0 | Y32: 0 | Z32: 0.0834
B33: RPU_OFF_1_SP370_HH150 | C33: NoSubset | D33: OFF-1-SP370-HH150 | E33: =ROW(D33)-ROW($E$5) -> 28 | F33: 1 | G33: SP370-HH150-v1 | H33: 0 | I33: - | J33: 1 | K33: 0 | L33: 0 | M33: 0 | N33: 24000 | O33: 0 | P33: 0 | Q33: 0 | R33: 1 | S33: 1 | T33: 0 | U33: 5288 | V33: =U33*0.02 -> 105.76 | W33: 0.0031 | X33: 0 | Y33: 0 | Z33: 0.0834
B34: RPU_OFF_2_SP316_HH150 | C34: NoSubset | D34: OFF-2-SP316-HH150 | E34: =ROW(D34)-ROW($E$5) -> 29 | F34: 1 | G34: SP316-HH150 | H34: 0 | I34: - | J34: 1 | K34: 0 | L34: 0 | M34: 0 | N34: 10000000 | O34: 0 | P34: 0 | Q34: 0 | R34: 1 | S34: 1 | T34: 0 | U34: 4823 | V34: =U34*0.02 -> 96.46 | W34: 0.0031 | X34: 0 | Y34: 0 | Z34: 0.0834
B35: RPU_OFF_2_SP370_HH150 | C35: NoSubset | D35: OFF-2-SP370-HH150 | E35: =ROW(D35)-ROW($E$5) -> 30 | F35: 1 | G35: SP370-HH150 | H35: 0 | I35: - | J35: 1 | K35: 0 | L35: 0 | M35: 0 | N35: 60000000 | O35: 0 | P35: 0 | Q35: 0 | R35: 1 | S35: 1 | T35: 0 | U35: 5288 | V35: =U35*0.02 -> 105.76 | W35: 0.0031 | X35: 0 | Y35: 0 | Z35: 0.0834
B36: PU_Grid_in | C36: Grid_buy | D36: Electricity from the grid | E36: =ROW(D36)-ROW($E$5) -> 31 | F36: 0 | G36: Power_from_the_grid | H36: 0 | I36: - | J36: 1 | K36: 0 | L36: 0 | M36: 0 | N36: 20000000 | O36: 0 | P36: 0 | Q36: 0 | R36: 1 | S36: 1 | T36: 0 | U36: 66 | V36: 0 | W36: 0 | X36: 0 | Y36: 0.01665 | Z36: 0.085803265
B37: Grid_out | C37: NoSubset | D37: Curtailment | E37: =ROW(D37)-ROW($E$5) -> 32 | F37: 1 | G37: Power_to_the_grid | H37: 0 | I37: - | J37: -1 | K37: 0 | L37: 0 | M37: 0 | N37: 20000000 | O37: 0 | P37: 0 | Q37: 0 | R37: 1 | S37: 1 | T37: 0 | U37: 0 | V37: 0 | W37: 0 | X37: 0 | Y37: 0 | Z37: 0
B38: Stor_in | C38: NoSubset | D38: Charge batteries | E38: =ROW(D38)-ROW($E$5) -> 33 | F38: 1 | G38: Electricity_to_batteries | H38: 0 | I38: - | J38: -1 | K38: 0 | L38: 0 | M38: 0 | N38: 20000000 | O38: 0 | P38: 0 | Q38: 0 | R38: 1 | S38: 1 | T38: 0.04 | U38: 0 | V38: 0 | W38: 0.00208558 | X38: 0 | Y38: 0 | Z38: 0
B39: Stor_out | C39: NoSubset | D39: Discharge batteries | E39: =ROW(D39)-ROW($E$5) -> 34 | F39: 1 | G39: Electricity_from_batteries | H39: 0 | I39: - | J39: 1 | K39: 0 | L39: 0 | M39: 0 | N39: 20000000 | O39: 0 | P39: 0 | Q39: 0 | R39: 1 | S39: 1 | T39: 0.05 | U39: 0 | V39: 0 | W39: 0 | X39: 0 | Y39: 0 | Z39: 0
B40: Tank | C40: NoSubset | D40: Batteries | E40: =ROW(D40)-ROW($E$5) -> 35 | F40: 1 | G40: Electricity_stored | H40: 0 | I40: - | J40: 0 | K40: 0 | L40: 0 | M40: 0 | N40: 20000000 | O40: 0 | P40: 0 | Q40: 0.2 | R40: 1 | S40: 1 | T40: 0 | U40: 361.82973 | V40: 5.0761 | W40: 0 | X40: 0 | Y40: 0 | Z40: 0.094392926

Sheet Selected_units
B1: Fuel produced | C1: NH3 | D1: NH3 | E1: NH3 | F1: NH3 | G1: NH3 | H1: NH3 | I1: NH3 | J1: NH3
B2: Fuel energy content LHV (MJ/kg fuel) | C2: 18.6 | D2: 18.6 | E2: 18.6 | F2: 18.6 | G2: 18.6 | H2: 18.6 | I2: 18.6 | J2: 18.6
B3: Electrolyser | C3: AEC | D3: SOEC | E3: AEC | F3: SOEC | G3: AEC | H3: SOEC | I3: AEC | J3: SOEC
B4: Carbon capture | C4: None | D4: None | E4: None | F4: None | G4: None | H4: None | I4: None | J4: None
B5: CSP technology | C5: Tower50 | D5: Tower50 | E5: Tower100 | F5: Tower100 | G5: Parabolic50 | H5: Parabolic50 | I5: Parabolic100 | J5: Parabolic100
B6: Configuration | C6: =C1&"_"&C3&"_"&C4&"_"&C5 -> NH3_AEC_None_Tower50 | D6: =D1&"_"&D3&"_"&D4&"_"&D5 -> NH3_SOEC_None_Tower50 | E6: =E1&"_"&E3&"_"&E4&"_"&E5 -> NH3_AEC_None_Tower100 | F6: =F1&"_"&F3&"_"&F4&"_"&F5 -> NH3_SOEC_None_Tower100 | G6: =G1&"_"&G3&"_"&G4&"_"&G5 -> NH3_AEC_None_Parabolic50 | H6: =H1&"_"&H3&"_"&H4&"_"&H5 -> NH3_SOEC_None_Parabolic50 | I6: =I1&"_"&I3&"_"&I4&"_"&I5 -> NH3_AEC_None_Parabolic100 | J6: =J1&"_"&J3&"_"&J4&"_"&J5 -> NH3_SOEC_None_Parabolic100
A7: 1 | B7: =Data_base_case!D6 -> NH3 plant + ASU - AEC | C7: 1 | D7: 0 | E7: 1 | F7: 0 | G7: 1 | H7: 0 | I7: 1 | J7: 0
A8: =A7+1 -> 2 | B8: =Data_base_case!D7 -> NH3 plant + ASU - SOEC | C8: 0 | D8: 1 | E8: 0 | F8: 1 | G8: 0 | H8: 1 | I8: 0 | J8: 1
A9: =A8+1 -> 3 | B9: =Data_base_case!D8 -> Desalination plant | C9: 1 | D9: 1 | E9: 1 | F9: 1 | G9: 1 | H9: 1 | I9: 1 | J9: 1
A10: =A9+1 -> 4 | B10: =Data_base_case!D9 -> Electrolyser AEC | C10: 1 | D10: 0 | E10: 1 | F10: 0 | G10: 1 | H10: 0 | I10: 1 | J10: 0
A11: =A10+1 -> 5 | B11: =Data_base_case!D10 -> Electrolyser SOEC | C11: 0 | D11: 1 | E11: 0 | F11: 1 | G11: 0 | H11: 1 | I11: 0 | J11: 1
A12: =A11+1 -> 6 | B12: =Data_base_case!D11 -> H2 pipeline to NH3 plant | C12: 1 | D12: 1 | E12: 1 | F12: 1 | G12: 1 | H12: 1 | I12: 1 | J12: 1
A13: =A12+1 -> 7 | B13: =Data_base_case!D12 -> Sale of oxygen | C13: 1 | D13: 1 | E13: 1 | F13: 1 | G13: 1 | H13: 1 | I13: 1 | J13: 1
A14: =A13+1 -> 8 | B14: =Data_base_case!D13 -> Heat from district heating | C14: 1 | D14: 1 | E14: 1 | F14: 1 | G14: 1 | H14: 1 | I14: 1 | J14: 1
A15: =A14+1 -> 9 | B15: =Data_base_case!D14 -> Heat sent to district heating | C15: 1 | D15: 1 | E15: 1 | F15: 1 | G15: 1 | H15: 1 | I15: 1 | J15: 1
A16: =A15+1 -> 10 | B16: =Data_base_case!D15 -> H2 pipes compressor | C16: 1 | D16: 1 | E16: 1 | F16: 1 | G16: 1 | H16: 1 | I16: 1 | J16: 1
A17: =A16+1 -> 11 | B17: =Data_base_case!D16 -> H2 pipes valve | C17: 1 | D17: 1 | E17: 1 | F17: 1 | G17: 1 | H17: 1 | I17: 1 | J17: 1
A18: =A17+1 -> 12 | B18: =Data_base_case!D17 -> H2 buried pipes | C18: 1 | D18: 1 | E18: 1 | F18: 1 | G18: 1 | H18: 1 | I18: 1 | J18: 1
A19: =A18+1 -> 13 | B19: =Data_base_case!D18 -> Solar tracking | C19: 1 | D19: 1 | E19: 1 | F19: 1 | G19: 1 | H19: 1 | I19: 1 | J19: 1
... A41: =A40+1 -> 35 | B41: =Data_base_case!D40 -> Batteries | C41: 1 | D41: 1 | E41: 1 | F41: 1 | G41: 1 | H41: 1 | I41: 1 | J41: 1

Sheet Scenarios_definition
A1: Changes also include the changes made in the reference scenario. If nothing is specified in the reference scenario column, changes are made compared to the input data sheet (i.e Data_base_case)
A2: Change are made compared to the reference scenario. "Chains" of reference scenarios doesn't work.
A4: Reference scenario | B4: Scenario name definition | C4: Type of units for change | D4: Parameter changed | E4: Year new value | F4: New value | G4: Year old value | H4: Old value
B5: Islanded | C5: Electricity from the grid | D5: Used (1 or 0) | E5: 2020 | F5: 0 | G5: 2020 | H5: =INDEX(Data_base_case!$D$4:$Y$40,MATCH(Scenarios_definition!C5,Data_base_case!$D$4:$D$40,0),MATCH(Scenarios_definition!D5&Scenarios_definition!G5,Data_base_case!$D$4:$Y$4,0)) -> 0
B6: CSP_only | C6: Solar tracking | D6: Used (1 or 0) | E6: 2020 | F6: 0 | G6: 2020 | H6: =INDEX(Data_base_case!$D$4:$Y$40,MATCH(Scenarios_definition!C6,Data_base_case!$D$4:$D$40,0),MATCH(Scenarios_definition!D6&Scenarios_definition!G6,Data_base_case!$D$4:$Y$4,0)) -> 1
B7: CSP_only | C7: ON-SP277-HH100 | D7: Used (1 or 0) | E7: 2020 | F7: 0 | G7: 2020 | H7: =INDEX(Data_base_case!$D$4:$Y$40,MATCH(Scenarios_definition!C7,Data_base_case!$D$4:$D$40,0),MATCH(Scenarios_definition!D7&Scenarios_definition!G7,Data_base_case!$D$4:$Y$4,0)) -> 1
B8: CSP_only | C8: ON-SP335-HH100 | D8: Used (1 or 0) | E8: 2020 | F8: 0 | G8: 2020 | H8: =INDEX(Data_base_case!$D$4:$Y$40,MATCH(Scenarios_definition!C8,Data_base_case!$D$4:$D$40,0),MATCH(Scenarios_definition!D8&Scenarios_definition!G8,Data_base_case!$D$4:$Y$4,0)) -> 1
B9: CSP_only | C9: OFF-1-SP316-HH150 | D9: Used (1 or 0) | E9: 2020 | F9: 0 | G9: 2020 | H9: =INDEX(Data_base_case!$D$4:$Y$40,MATCH(Scenarios_definition!C9,Data_base_case!$D$4:$D$40,0),MATCH(Scenarios_definition!D9&Scenarios_definition!G9,Data_base_case!$D$4:$Y$4,0)) -> 1
B10: CSP_only | C10: OFF-1-SP370-HH150 | D10: Used (1 or 0) | E10: 2020 | F10: 0 | G10: 2020 | H10: =INDEX(Data_base_case!$D$4:$Y$40,MATCH(Scenarios_definition!C10,Data_base_case!$D$4:$D$40,0),MATCH(Scenarios_definition!D10&Scenarios_definition!G10,Data_base_case!$D$4:$Y$4,0)) -> 1
B11: CSP+TES-85% | C11: CSP Plant tower 50 MW | D11: Investment (EUR/Capacity installed) | E11: 2020 | F11: =H11*I11 -> 516.0693 | G11: 2020 | H11: =INDEX(Data_base_case!$D$4:$Y$40,MATCH(Scenarios_definition!C11,Data_base_case!$D$4:$D$40,0),MATCH(Scenarios_definition!D11&Scenarios_definition!G11,Data_base_case!$D$4:$Y$4,0)) -> 3440.462 | I11: 0.15
B12: CSP+TES-85% | C12: TES ST 50 MW | D12: Investment (EUR/Capacity installed) | E12: 2020 | F12: =H12*I12 -> 5.7341033 | G12: 2020 | H12: =INDEX(Data_base_case!$D$4:$Y$40,MATCH(Scenarios_definition!C12,Data_base_case!$D$4:$D$40,0),MATCH(Scenarios_definition!D12&Scenarios_definition!G12,Data_base_case!$D$4:$Y$4,0)) -> 38.227356 | I12: 0.15
B13: CSP+TES-80% | C13: CSP Plant tower 50 MW | D13: Investment (EUR/Capacity installed) | E13: 2020 | F13: =H13*I13 -> 688.0924 | G13: 2020 | H13: =INDEX(Data_base_case!$D$4:$Y$40,MATCH(Scenarios_definition!C13,Data_base_case!$D$4:$D$40,0),MATCH(Scenarios_definition!D13&Scenarios_definition!G13,Data_base_case!$D$4:$Y$4,0)) -> 3440.462 | I13: 0.2
B14: CSP+TES-80% | C14: TES ST 50 MW | D14: Investment (EUR/Capacity installed) | E14: 2020 | F14: =H14*I14 -> 7.6454711 | G14: 2020 | H14: =INDEX(Data_base_case!$D$4:$Y$40,MATCH(Scenarios_definition!C14,Data_base_case!$D$4:$D$40,0),MATCH(Scenarios_definition!D14&Scenarios_definition!G14,Data_base_case!$D$4:$Y$4,0)) -> 38.227356 | I14: 0.2
B15: CSP+TES-75% | C15: CSP Plant tower 50 MW | D15: Investment (EUR/Capacity installed) | E15: 2020 | F15: =H15*I15 -> 860.1155 | G15: 2020 | H15: =INDEX(Data_base_case!$D$4:$Y$40,MATCH(Scenarios_definition!C15,Data_base_case!$D$4:$D$40,0),MATCH(Scenarios_definition!D15&Scenarios_definition!G15,Data_base_case!$D$4:$Y$4,0)) -> 3440.462 | I15: 0.25
B16: CSP+TES-75% | C16: TES ST 50 MW | D16: Investment (EUR/Capacity installed) | E16: 2020 | F16: =H16*I16 -> 9.5568389 | G16: 2020 | H16: =INDEX(Data_base_case!$D$4:$Y$40,MATCH(Scenarios_definition!C16,Data_base_case!$D$4:$D$40,0),MATCH(Scenarios_definition!D16&Scenarios_definition!G16,Data_base_case!$D$4:$Y$4,0)) -> 38.227356 | I16: 0.25
B17: CSP+TES-60% | C17: CSP Plant tower 50 MW | D17: Investment (EUR/Capacity installed) | E17: 2020 | F17: =H17*I17 -> 1376.1848 | G17: 2020 | H17: =INDEX(Data_base_case!$D$4:$Y$40,MATCH(Scenarios_definition!C17,Data_base_case!$D$4:$D$40,0),MATCH(Scenarios_definition!D17&Scenarios_definition!G17,Data_base_case!$D$4:$Y$4,0)) -> 3440.462 | I17: 0.4
B18: CSP+TES-60% | C18: TES ST 50 MW | D18: Investment (EUR/Capacity installed) | E18: 2020 | F18: =H18*I18 -> 15.290942 | G18: 2020 | H18: =INDEX(Data_base_case!$D$4:$Y$40,MATCH(Scenarios_definition!C18,Data_base_case!$D$4:$D$40,0),MATCH(Scenarios_definition!D18&Scenarios_definition!G18,Data_base_case!$D$4:$Y$4,0)) -> 38.227356 | I18: 0.4
B19: CSP+TES-55% | C19: CSP Plant tower 50 MW | D19: Investment (EUR/Capacity installed) | E19: 2020 | F19: =H19*I19 -> 1548.2079 | G19: 2020 | H19: =INDEX(Data_base_case!$D$4:$Y$40,MATCH(Scenarios_definition!C19,Data_base_case!$D$4:$D$40,0),MATCH(Scenarios_definition!D19&Scenarios_definition!G19,Data_base_case!$D$4:$Y$4,0)) -> 3440.462 | I19: 0.45
B20: CSP+TES-55% | C20: TES ST 50 MW | D20: Investment (EUR/Capacity installed) | E20: 2020 | F20: =H20*I20 -> 17.20231 | G20: 2020 | H20: =INDEX(Data_base_case!$D$4:$Y$40,MATCH(Scenarios_definition!C20,Data_base_case!$D$4:$D$40,0),MATCH(Scenarios_definition!D20&Scenarios_definition!G20,Data_base_case!$D$4:$Y$4,0)) -> 38.227356 | I20: 0.45
B21: CSP+TES-50% | C21: CSP Plant tower 50 MW | D21: Investment (EUR/Capacity installed) | E21: 2020 | F21: =H21*I21 -> 1720.231 | G21: 2020 | H21: =INDEX(Data_base_case!$D$4:$Y$40,MATCH(Scenarios_definition!C21,Data_base_case!$D$4:$D$40,0),MATCH(Scenarios_definition!D21&Scenarios_definition!G21,Data_base_case!$D$4:$Y$4,0)) -> 3440.462 | I21: 0.5
B22: CSP+TES-50% | C22: TES ST 50 MW | D22: Investment (EUR/Capacity installed) | E22: 2020 | F22: =H22*I22 -> 19.113678 | G22: 2020 | H22: =INDEX(Data_base_case!$D$4:$Y$40,MATCH(Scenarios_definition!C22,Data_base_case!$D$4:$D$40,0),MATCH(Scenarios_definition!D22&Scenarios_definition!G22,Data_base_case!$D$4:$Y$4,0)) -> 38.227356 | I22: 0.5
... B40: CSP+TES+50% | C40: TES ST 50 MW | D40: Investment (EUR/Capacity installed) | E40: 2020 | F40: =H40*I40 -> 57.341033 | G40: 2020 | H40: =INDEX(Data_base_case!$D$4:$Y$40,MATCH(Scenarios_definition!C40,Data_base_case!$D$4:$D$40,0),MATCH(Scenarios_definition!D40&Scenarios_definition!G40,Data_base_case!$D$4:$Y$4,0)) -> 38.227356 | I40: 1.5
B41: Batteries-50% | C41: Batteries | D41: Investment (EUR/Capacity installed) | E41: ="2020" -> 2020 | F41: =H41*I41 -> 180.91487 | G41: 2020 | H41: =INDEX(Data_base_case!$D$4:$Y$40,MATCH(Scenarios_definition!C41,Data_base_case!$D$4:$D$40,0),MATCH(Scenarios_definition!D41&Scenarios_definition!G41,Data_base_case!$D$4:$Y$4,0)) -> 361.82973 | I41: 0.5
B42: Batteries-40% | C42: Batteries | D42: Investment (EUR/Capacity installed) | E42: ="2020" -> 2020 | F42: =H42*I42 -> 217.09784 | G42: 2020 | H42: =INDEX(Data_base_case!$D$4:$Y$40,MATCH(Scenarios_definition!C42,Data_base_case!$D$4:$D$40,0),MATCH(Scenarios_definition!D42&Scenarios_definition!G42,Data_base_case!$D$4:$Y$4,0)) -> 361.82973 | I42: 0.6
B43: Batteries-30% | C43: Batteries | D43: Investment (EUR/Capacity installed) | E43: ="2020" -> 2020 | F43: =H43*I43 -> 253.28081 | G43: 2020 | H43: =INDEX(Data_base_case!$D$4:$Y$40,MATCH(Scenarios_definition!C43,Data_base_case!$D$4:$D$40,0),MATCH(Scenarios_definition!D43&Scenarios_definition!G43,Data_base_case!$D$4:$Y$4,0)) -> 361.82973 | I43: 0.7
B44: Batteries-20% | C44: Batteries | D44: Investment (EUR/Capacity installed) | E44: ="2020" -> 2020 | F44: =H44*I44 -> 289.46379 | G44: 2020 | H44: =INDEX(Data_base_case!$D$4:$Y$40,MATCH(Scenarios_definition!C44,Data_base_case!$D$4:$D$40,0),MATCH(Scenarios_definition!D44&Scenarios_definition!G44,Data_base_case!$D$4:$Y$4,0)) -> 361.82973 | I44: 0.8
B45: Batteries-10% | C45: Batteries | D45: Investment (EUR/Capacity installed) | E45: ="2020" -> 2020 | F45: =H45*I45 -> 325.64676 | G45: 2020 | H45: =INDEX(Data_base_case!$D$4:$Y$40,MATCH(Scenarios_definition!C45,Data_base_case!$D$4:$D$40,0),MATCH(Scenarios_definition!D45&Scenarios_definition!G45,Data_base_case!$D$4:$Y$4,0)) -> 361.82973 | I45: 0.9
B46: Batteries+10% | C46: Batteries | D46: Investment (EUR/Capacity installed) | E46: ="2020" -> 2020 | F46: =H46*I46 -> 398.01271 | G46: 2020 | H46: =INDEX(Data_base_case!$D$4:$Y$40,MATCH(Scenarios_definition!C46,Data_base_case!$D$4:$D$40,0),MATCH(Scenarios_definition!D46&Scenarios_definition!G46,Data_base_case!$D$4:$Y$4,0)) -> 361.82973 | I46: 1.1
B47: Batteries+20% | C47: Batteries | D47: Investment (EUR/Capacity installed) | E47: ="2020" -> 2020 | F47: =H47*I47 -> 434.19568 | G47: 2020 | H47: =INDEX(Data_base_case!$D$4:$Y$40,MATCH(Scenarios_definition!C47,Data_base_case!$D$4:$D$40,0),MATCH(Scenarios_definition!D47&Scenarios_definition!G47,Data_base_case!$D$4:$Y$4,0)) -> 361.82973 | I47: 1.2
B48: Batteries+30% | C48: Batteries | D48: Investment (EUR/Capacity installed) | E48: ="2020" -> 2020 | F48: =H48*I48 -> 470.37865 | G48: 2020 | H48: =INDEX(Data_base_case!$D$4:$Y$40,MATCH(Scenarios_definition!C48,Data_base_case!$D$4:$D$40,0),MATCH(Scenarios_definition!D48&Scenarios_definition!G48,Data_base_case!$D$4:$Y$4,0)) -> 361.82973 | I48: 1.3
B49: Batteries+40% | C49: Batteries | D49: Investment (EUR/Capacity installed) | E49: ="2020" -> 2020 | F49: =H49*I49 -> 506.56163 | G49: 2020 | H49: =INDEX(Data_base_case!$D$4:$Y$40,MATCH(Scenarios_definition!C49,Data_base_case!$D$4:$D$40,0),MATCH(Scenarios_definition!D49&Scenarios_definition!G49,Data_base_case!$D$4:$Y$4,0)) -> 361.82973 | I49: 1.4
B50: Batteries+50% | C50: Batteries | D50: Investment (EUR/Capacity installed) | E50: ="2020" -> 2020 | F50: =H50*I50 -> 542.7446 | G50: 2020 | H50: =INDEX(Data_base_case!$D$4:$Y$40,MATCH(Scenarios_definition!C50,Data_base_case!$D$4:$D$40,0),MATCH(Scenarios_definition!D50&Scenarios_definition!G50,Data_base_case!$D$4:$Y$4,0)) -> 361.82973 | I50: 1.5
B51: H2storage-50% | C51: H2 buried pipes | D51: Investment (EUR/Capacity installed) | E51: ="2020" -> 2020 | F51: =H51*I51 -> 230.37771 | G51: 2020 | H51: =INDEX(Data_base_case!$D$4:$Y$40,MATCH(Scenarios_definition!C51,Data_base_case!$D$4:$D$40,0),MATCH(Scenarios_definition!D51&Scenarios_definition!G51,Data_base_case!$D$4:$Y$4,0)) -> 460.75542 | I51: 0.5
B52: H2storage-40% | C52: H2 buried pipes | D52: Investment (EUR/Capacity installed) | E52: ="2020" -> 2020 | F52: =H52*I52 -> 276.45325 | G52: 2020 | H52: =INDEX(Data_base_case!$D$4:$Y$40,MATCH(Scenarios_definition!C52,Data_base_case!$D$4:$D$40,0),MATCH(Scenarios_definition!D52&Scenarios_definition!G52,Data_base_case!$D$4:$Y$4,0)) -> 460.75542 | I52: 0.6
... B89: AEC+200% | C89: Electrolyser AEC | D89: Fixed cost (EUR/Capacity installed/y) | E89: ="2020" -> 2020 | F89: =H89*I89 -> 2811.78 | G89: 2020 | H89: =INDEX(Data_base_case!$D$4:$Y$40,MATCH(Scenarios_definition!C89,Data_base_case!$D$4:$D$40,0),MATCH(Scenarios_definition!D89&Scenarios_definition!G89,Data_base_case!$D$4:$Y$4,0)) -> 937.26 | I89: 3
B90: CSP_VarOM-5.5 | C90: CSP Plant tower 50 MW | D90: Variable cost (EUR/Output) | E90: ="2020" -> 2020 | F90: =I90/1000 -> 0.0055 | G90: 2020 | H90: =INDEX(Data_base_case!$D$4:$Y$40,MATCH(Scenarios_definition!C90,Data_base_case!$D$4:$D$40,0),MATCH(Scenarios_definition!D90&Scenarios_definition!G90,Data_base_case!$D$4:$Y$4,0)) -> 0.0045833715 | I90: 5.5
B91: CSP_VarOM-5 | C91: CSP Plant tower 50 MW | D91: Variable cost (EUR/Output) | E91: ="2020" -> 2020 | F91: =I91/1000 -> 0.005 | G91: 2020 | H91: =INDEX(Data_base_case!$D$4:$Y$40,MATCH(Scenarios_definition!C91,Data_base_case!$D$4:$D$40,0),MATCH(Scenarios_definition!D91&Scenarios_definition!G91,Data_base_case!$D$4:$Y$4,0)) -> 0.0045833715 | I91: 5
B92: CSP_VarOM-4.5 | C92: CSP Plant tower 50 MW | D92: Variable cost (EUR/Output) | E92: ="2020" -> 2020 | F92: =I92/1000 -> 0.0045 | G92: 2020 | H92: =INDEX(Data_base_case!$D$4:$Y$40,MATCH(Scenarios_definition!C92,Data_base_case!$D$4:$D$40,0),MATCH(Scenarios_definition!D92&Scenarios_definition!G92,Data_base_case!$D$4:$Y$4,0)) -> 0.0045833715 | I92: 4.5
B93: CSP_VarOM-4 | C93: CSP Plant tower 50 MW | D93: Variable cost (EUR/Output) | E93: ="2020" -> 2020 | F93: =I93/1000 -> 0.004 | G93: 2020 | H93: =INDEX(Data_base_case!$D$4:$Y$40,MATCH(Scenarios_definition!C93,Data_base_case!$D$4:$D$40,0),MATCH(Scenarios_definition!D93&Scenarios_definition!G93,Data_base_case!$D$4:$Y$4,0)) -> 0.0045833715 | I93: 4
B94: CSP_VarOM-3.5 | C94: CSP Plant tower 50 MW | D94: Variable cost (EUR/Output) | E94: ="2020" -> 2020 | F94: =I94/1000 -> 0.0035 | G94: 2020 | H94: =INDEX(Data_base_case!$D$4:$Y$40,MATCH(Scenarios_definition!C94,Data_base_case!$D$4:$D$40,0),MATCH(Scenarios_definition!D94&Scenarios_definition!G94,Data_base_case!$D$4:$Y$4,0)) -> 0.0045833715 | I94: 3.5
...

Sheet ScenariosToRun
B1: Options available
B2: Name of the scenario in the output csv file | C2: See Scenarios_definition | D2: Antofagasta | E2: NH3 | F2: None | G2: Tower50 | H2: 2020 | I2: Folder name where the excel profile is | J2: Name of the excel file profile | K2: AEC | L2: Any data sheet name | M2: Any name
G3: Tower100 | K3: SOEC
G4: Parabolic50
G5: Parabolic100 | S5: Results to write
A7: Scenario number | B7: Scenario name | C7: Scenario | D7: Location | E7: Fuel | F7: CO2 capture | G7: CSP tech | H7: Year data | I7: Profile folder name | J7: Profile name | K7: Electrolyser | L7: Input data sheet | M7: Result folder name | N7: Max capacity | O7: Ramping | P7: No negative elec price | Q7: Fixed heat sale | R7: Fixed oxygen sale | S7: Flows
A8: =ROW(A8)-ROW($A$7) -> 1 | B8: All_options | C8: Islanded | D8: Antofagasta | E8: NH3 | F8: None | G8: Tower50 | H8: 2020 | I8: Antofagasta | J8: Antofagasta_2020 | K8: AEC | L8: Data_base_case | M8: Results_main_CSPstudy | N8: FALSE | O8: FALSE | P8: TRUE | Q8: FALSE | R8: FALSE | S8: TRUE
A9: =ROW(A9)-ROW($A$7) -> 2 | B9: All_options | C9: Islanded | D9: Antofagasta | E9: NH3 | F9: None | G9: Tower100 | H9: 2020 | I9: Antofagasta | J9: Antofagasta_2020 | K9: SOEC | L9: Data_base_case | M9: Results_main_CSPstudy | N9: FALSE | O9: FALSE | P9: TRUE | Q9: FALSE | R9: FALSE | S9: TRUE
A10: =ROW(A10)-ROW($A$7) -> 3 | B10: CSP_only | C10: CSP_only | D10: Antofagasta | E10: NH3 | F10: None | G10: Tower100 | H10: 2020 | I10: Antofagasta | J10: Antofagasta_2020 | K10: AEC | L10: Data_base_case | M10: Results_main_CSPstudy | N10: FALSE | O10: FALSE | P10: TRUE | Q10: FALSE | R10: FALSE | S10: TRUE
A11: =ROW(A11)-ROW($A$7) -> 4 | B11: CSP_only | C11: CSP_only | D11: Antofagasta | E11: NH3 | F11: None | G11: Tower100 | H11: 2020 | I11: Antofagasta | J11: Antofagasta_2020 | K11: SOEC | L11: Data_base_case | M11: Results_main_CSPstudy | N11: FALSE | O11: FALSE | P11: TRUE | Q11: FALSE | R11: FALSE | S11: TRUE
A12: =ROW(A12)-ROW($A$7) -> 5 | B12: CSP+TES-50% | C12: =B12 -> CSP+TES-50% | D12: Antofagasta | E12: NH3 | F12: None | G12: Tower50 | H12: 2020 | I12: Antofagasta | J12: Antofagasta_2020 | K12: AEC | L12: Data_base_case | M12: Results_main_CSPstudy | N12: FALSE | O12: FALSE | P12: TRUE | Q12: FALSE | R12: FALSE | S12: TRUE
A13: =ROW(A13)-ROW($A$7) -> 6 | B13: CSP+TES-40% | C13: =B13 -> CSP+TES-40% | D13: Antofagasta | E13: NH3 | F13: None | G13: Tower50 | H13: 2020 | I13: Antofagasta | J13: Antofagasta_2020 | K13: AEC | L13: Data_base_case | M13: Results_main_CSPstudy | N13: FALSE | O13: FALSE | P13: TRUE | Q13: FALSE | R13: FALSE | S13: TRUE
A14: =ROW(A14)-ROW($A$7) -> 7 | B14: CSP+TES-30% | C14: =B14 -> CSP+TES-30% | D14: Antofagasta | E14: NH3 | F14: None | G14: Tower50 | H14: 2020 | I14: Antofagasta | J14: Antofagasta_2020 | K14: AEC | L14: Data_base_case | M14: Results_main_CSPstudy | N14: FALSE | O14: FALSE | P14: TRUE | Q14: FALSE | R14: FALSE | S14: TRUE
A15: =ROW(A15)-ROW($A$7) -> 8 | B15: CSP+TES-20% | C15: =B15 -> CSP+TES-20% | D15: Antofagasta | E15: NH3 | F15: None | G15: Tower50 | H15: 2020 | I15: Antofagasta | J15: Antofagasta_2020 | K15: AEC | L15: Data_base_case | M15: Results_main_CSPstudy | N15: FALSE | O15: FALSE | P15: TRUE | Q15: FALSE | R15: FALSE | S15: TRUE
A16: =ROW(A16)-ROW($A$7) -> 9 | B16: CSP+TES-10% | C16: =B16 -> CSP+TES-10% | D16: Antofagasta | E16: NH3 | F16: None | G16: Tower50 | H16: 2020 | I16: Antofagasta | J16: Antofagasta_2020 | K16: AEC | L16: Data_base_case | M16: Results_main_CSPstudy | N16: FALSE | O16: FALSE | P16: TRUE | Q16: FALSE | R16: FALSE | S16: TRUE
A17: =ROW(A17)-ROW($A$7) -> 10 | B17: CSP+TES+10% | C17: =B17 -> CSP+TES+10% | D17: Antofagasta | E17: NH3 | F17: None | G17: Tower50 | H17: 2020 | I17: Antofagasta | J17: Antofagasta_2020 | K17: AEC | L17: Data_base_case | M17: Results_main_CSPstudy | N17: FALSE | O17: FALSE | P17: TRUE | Q17: FALSE | R17: FALSE | S17: TRUE
A18: =ROW(A18)-ROW($A$7) -> 11 | B18: CSP+TES+20% | C18: =B18 -> CSP+TES+20% | D18: Antofagasta | E18: NH3 | F18: None | G18: Tower50 | H18: 2020 | I18: Antofagasta | J18: Antofagasta_2020 | K18: AEC | L18: Data_base_case | M18: Results_main_CSPstudy | N18: FALSE | O18: FALSE | P18: TRUE | Q18: FALSE | R18: FALSE | S18: TRUE
A19: =ROW(A19)-ROW($A$7) -> 12 | B19: CSP+TES+30% | C19: =B19 -> CSP+TES+30% | D19: Antofagasta | E19: NH3 | F19: None | G19: Tower50 | H19: 2020 | I19: Antofagasta | J19: Antofagasta_2020 | K19: AEC | L19: Data_base_case | M19: Results_main_CSPstudy | N19: FALSE | O19: FALSE | P19: TRUE | Q19: FALSE | R19: FALSE | S19: TRUE
A20: =ROW(A20)-ROW($A$7) -> 13 | B20: CSP+TES+40% | C20: =B20 -> CSP+TES+40% | D20: Antofagasta | E20: NH3 | F20: None | G20: Tower50 | H20: 2020 | I20: Antofagasta | J20: Antofagasta_2020 | K20: AEC | L20: Data_base_case | M20: Results_main_CSPstudy | N20: FALSE | O20: FALSE | P20: TRUE | Q20: FALSE | R20: FALSE | S20: TRUE
A21: =ROW(A21)-ROW($A$7) -> 14 | B21: CSP+TES+50% | C21: =B21 -> CSP+TES+50% | D21: Antofagasta | E21: NH3 | F21: None | G21: Tower50 | H21: 2020 | I21: Antofagasta | J21: Antofagasta_2020 | K21: AEC | L21: Data_base_case | M21: Results_main_CSPstudy | N21: FALSE | O21: FALSE | P21: TRUE | Q21: FALSE | R21: FALSE | S21: TRUE
A22: =ROW(A22)-ROW($A$7) -> 15 | B22: Batteries-50% | C22: Batteries-50% | D22: Antofagasta | E22: NH3 | F22: None | G22: Tower50 | H22: 2020 | I22: Antofagasta | J22: Antofagasta_2020 | K22: AEC | L22: Data_base_case | M22: Results_main_CSPstudy | N22: FALSE | O22: FALSE | P22: TRUE | Q22: FALSE | R22: FALSE | S22: TRUE
A23: =ROW(A23)-ROW($A$7) -> 16 | B23: Batteries-40% | C23: Batteries-40% | D23: Antofagasta | E23: NH3 | F23: None | G23: Tower50 | H23: 2020 | I23: Antofagasta | J23: Antofagasta_2020 | K23: AEC | L23: Data_base_case | M23: Results_main_CSPstudy | N23: FALSE | O23: FALSE | P23: TRUE | Q23: FALSE | R23: FALSE | S23: TRUE
A24: =ROW(A24)-ROW($A$7) -> 17 | B24: Batteries-30% | C24: Batteries-30% | D24: Antofagasta | E24: NH3 | F24: None | G24: Tower50 | H24: 2020 | I24: Antofagasta | J24: Antofagasta_2020 | K24: AEC | L24: Data_base_case | M24: Results_main_CSPstudy | N24: FALSE | O24: FALSE | P24: TRUE | Q24: FALSE | R24: FALSE | S24: TRUE
A25: =ROW(A25)-ROW($A$7) -> 18 | B25: Batteries-20% | C25: Batteries-20% | D25: Antofagasta | E25: NH3 | F25: None | G25: Tower50 | H25: 2020 | I25: Antofagasta | J25: Antofagasta_2020 | K25: AEC | L25: Data_base_case | M25: Results_main_CSPstudy | N25: FALSE | O25: FALSE | P25: TRUE | Q25: FALSE | R25: FALSE | S25: TRUE
A26: =ROW(A26)-ROW($A$7) -> 19 | B26: Batteries-10% | C26: Batteries-10% | D26: Antofagasta | E26: NH3 | F26: None | G26: Tower50 | H26: 2020 | I26: Antofagasta | J26: Antofagasta_2020 | K26: AEC | L26: Data_base_case | M26: Results_main_CSPstudy | N26: FALSE | O26: FALSE | P26: TRUE | Q26: FALSE | R26: FALSE | S26: TRUE
A27: =ROW(A27)-ROW($A$7) -> 20 | B27: Batteries+10% | C27: Batteries+10% | D27: Antofagasta | E27: NH3 | F27: None | G27: Tower50 | H27: 2020 | I27: Antofagasta | J27: Antofagasta_2020 | K27: AEC | L27: Data_base_case | M27: Results_main_CSPstudy | N27: FALSE | O27: FALSE | P27: TRUE | Q27: FALSE | R27: FALSE | S27: TRUE
A28: =ROW(A28)-ROW($A$7) -> 21 | B28: Batteries+20% | C28: Batteries+20% | D28: Antofagasta | E28: NH3 | F28: None | G28: Tower50 | H28: 2020 | I28: Antofagasta | J28: Antofagasta_2020 | K28: AEC | L28: Data_base_case | M28: Results_main_CSPstudy | N28: FALSE | O28: FALSE | P28: TRUE | Q28: FALSE | R28: FALSE | S28: TRUE
A29: =ROW(A29)-ROW($A$7) -> 22 | B29: Batteries+30% | C29: Batteries+30% | D29: Antofagasta | E29: NH3 | F29: None | G29: Tower50 | H29: 2020 | I29: Antofagasta | J29: Antofagasta_2020 | K29: AEC | L29: Data_base_case | M29: Results_main_CSPstudy | N29: FALSE | O29: FALSE | P29: TRUE | Q29: FALSE | R29: FALSE | S29: TRUE
A30: =ROW(A30)-ROW($A$7) -> 23 | B30: Batteries+40% | C30: Batteries+40% | D30: Antofagasta | E30: NH3 | F30: None | G30: Tower50 | H30: 2020 | I30: Antofagasta | J30: Antofagasta_2020 | K30: AEC | L30: Data_base_case | M30: Results_main_CSPstudy | N30: FALSE | O30: FALSE | P30: TRUE | Q30: FALSE | R30: FALSE | S30: TRUE
A31: =ROW(A31)-ROW($A$7) -> 24 | B31: Batteries+50% | C31: Batteries+50% | D31: Antofagasta | E31: NH3 | F31: None | G31: Tower50 | H31: 2020 | I31: Antofagasta | J31: Antofagasta_2020 | K31: AEC | L31: Data_base_case | M31: Results_main_CSPstudy | N31: FALSE | O31: FALSE | P31: TRUE | Q31: FALSE | R31: FALSE | S31: TRUE
A32: =ROW(A32)-ROW($A$7) -> 25 | B32: H2storage-50% | C32: =B32 -> H2storage-50% | D32: Antofagasta | E32: NH3 | F32: None | G32: Tower50 | H32: 2020 | I32: Antofagasta | J32: Antofagasta_2020 | K32: AEC | L32: Data_base_case | M32: Results_main_CSPstudy | N32: FALSE | O32: FALSE | P32: TRUE | Q32: FALSE | R32: FALSE | S32: TRUE
A33: =ROW(A33)-ROW($A$7) -> 26 | B33: H2storage-40% | C33: =B33 -> H2storage-40% | D33: Antofagasta | E33: NH3 | F33: None | G33: Tower50 | H33: 2020 | I33: Antofagasta | J33: Antofagasta_2020 | K33: AEC | L33: Data_base_case | M33: Results_main_CSPstudy | N33: FALSE | O33: FALSE | P33: TRUE | Q33: FALSE | R33: FALSE | S33: TRUE
A34: =ROW(A34)-ROW($A$7) -> 27 | B34: H2storage-30% | C34: =B34 -> H2storage-30% | D34: Antofagasta | E34: NH3 | F34: None | G34: Tower50 | H34: 2020 | I34: Antofagasta | J34: Antofagasta_2020 | K34: AEC | L34: Data_base_case | M34: Results_main_CSPstudy | N34: FALSE | O34: FALSE | P34: TRUE | Q34: FALSE | R34: FALSE | S34: TRUE
A35: =ROW(A35)-ROW($A$7) -> 28 | B35: H2storage-20% | C35: =B35 -> H2storage-20% | D35: Antofagasta | E35: NH3 | F35: None | G35: Tower50 | H35: 2020 | I35: Antofagasta | J35: Antofagasta_2020 | K35: AEC | L35: Data_base_case | M35: Results_main_CSPstudy | N35: FALSE | O35: FALSE | P35: TRUE | Q35: FALSE | R35: FALSE | S35: TRUE
A36: =ROW(A36)-ROW($A$7) -> 29 | B36: H2storage-10% | C36: =B36 -> H2storage-10% | D36: Antofagasta | E36: NH3 | F36: None | G36: Tower50 | H36: 2020 | I36: Antofagasta | J36: Antofagasta_2020 | K36: AEC | L36: Data_base_case | M36: Results_main_CSPstudy | N36: FALSE | O36: FALSE | P36: TRUE | Q36: FALSE | R36: FALSE | S36: TRUE
A37: =ROW(A37)-ROW($A$7) -> 30 | B37: H2storage+10% | C37: =B37 -> H2storage+10% | D37: Antofagasta | E37: NH3 | F37: None | G37: Tower50 | H37: 2020 | I37: Antofagasta | J37: Antofagasta_2020 | K37: AEC | L37: Data_base_case | M37: Results_main_CSPstudy | N37: FALSE | O37: FALSE | P37: TRUE | Q37: FALSE | R37: FALSE | S37: TRUE
A38: =ROW(A38)-ROW($A$7) -> 31 | B38: H2storage+20% | C38: =B38 -> H2storage+20% | D38: Antofagasta | E38: NH3 | F38: None | G38: Tower50 | H38: 2020 | I38: Antofagasta | J38: Antofagasta_2020 | K38: AEC | L38: Data_base_case | M38: Results_main_CSPstudy | N38: FALSE | O38: FALSE | P38: TRUE | Q38: FALSE | R38: FALSE | S38: TRUE
A39: =ROW(A39)-ROW($A$7) -> 32 | B39: H2storage+30% | C39: =B39 -> H2storage+30% | D39: Antofagasta | E39: NH3 | F39: None | G39: Tower50 | H39: 2020 | I39: Antofagasta | J39: Antofagasta_2020 | K39: AEC | L39: Data_base_case | M39: Results_main_CSPstudy | N39: FALSE | O39: FALSE | P39: TRUE | Q39: FALSE | R39: FALSE | S39: TRUE
A40: =ROW(A40)-ROW($A$7) -> 33 | B40: H2storage+40% | C40: =B40 -> H2storage+40% | D40: Antofagasta | E40: NH3 | F40: None | G40: Tower50 | H40: 2020 | I40: Antofagasta | J40: Antofagasta_2020 | K40: AEC | L40: Data_base_case | M40: Results_main_CSPstudy | N40: FALSE | O40: FALSE | P40: TRUE | Q40: FALSE | R40: FALSE | S40: TRUE
A41: =ROW(A41)-ROW($A$7) -> 34 | B41: H2storage+50% | C41: =B41 -> H2storage+50% | D41: Antofagasta | E41: NH3 | F41: None | G41: Tower50 | H41: 2020 | I41: Antofagasta | J41: Antofagasta_2020 | K41: AEC | L41: Data_base_case | M41: Results_main_CSPstudy | N41: FALSE | O41: FALSE | P41: TRUE | Q41: FALSE | R41: FALSE | S41: TRUE
...

Sheet ScenariosAllCSP
C1: Options available
B2: Name of the scenario in the output csv file | C2: See Scenarios_definition | D2: Antofagasta | E2: NH3 | F2: 2020 | G2: AEC | H2: Tower50 | I2: Any data sheet | J2: Location_year | K2: Any name
G3: SOEC | H3: Tower100
H4: Parabolic50
H5: Parabolic100 | P5: Results to write
A7: Scenario number | B7: Scenario name | C7: Scenario | D7: Location | E7: Fuel | F7: Year | G7: Electrolyser | H7: CSP tech | I7: Input data sheet | J7: Profile name | K7: Result folder name | L7: Ramping | M7: No negative elec price | N7: Fixed heat sale | O7: Fixed oxygen sale | P7: Flows
A8: =ROW(A8)-ROW($A$7) -> 1 | B8: Islanded | C8: =B8 -> Islanded | D8: Antofagasta | E8: NH3 | F8: 2020 | G8: AEC | H8: Tower50 | I8: Data_base_case | J8: Antofagasta_2020 | K8: Results_main_pre-run | L8: FALSE | M8: TRUE | N8: FALSE | O8: FALSE | P8: FALSE
A9: =ROW(A9)-ROW($A$7) -> 2 | B9: Islanded | C9: =B9 -> Islanded | D9: Antofagasta | E9: NH3 | F9: 2020 | G9: AEC | H9: Parabolic50 | I9: Data_base_case | J9: Antofagasta_2020 | K9: Results_main_pre-run | L9: FALSE | M9: TRUE | N9: FALSE | O9: FALSE | P9: FALSE
A10: =ROW(A10)-ROW($A$7) -> 3 | B10: Islanded | C10: =B10 -> Islanded | D10: Antofagasta | E10: NH3 | F10: 2020 | G10: AEC | H10: Tower100 | I10: Data_base_case | J10: Antofagasta_2020 | K10: Results_main_pre-run | L10: FALSE | M10: TRUE | N10: FALSE | O10: FALSE | P10: FALSE
A11: =ROW(A11)-ROW($A$7) -> 4 | B11: Islanded | C11: =B11 -> Islanded | D11: Antofagasta | E11: NH3 | F11: 2020 | G11: AEC | H11: Parabolic100 | I11: Data_base_case | J11: Antofagasta_2020 | K11: Results_main_pre-run | L11: FALSE | M11: TRUE | N11: FALSE | O11: FALSE | P11: FALSE
A12: =ROW(A12)-ROW($A$7) -> 5 | B12: Islanded | C12: =B12 -> Islanded | D12: Antofagasta | E12: NH3 | F12: 2020 | G12: SOEC | H12: Tower50 | I12: Data_base_case | J12: Antofagasta_2020 | K12: Results_main_pre-run | L12: FALSE | M12: TRUE | N12: FALSE | O12: FALSE | P12: FALSE
A13: =ROW(A13)-ROW($A$7) -> 6 | B13: Islanded | C13: =B13 -> Islanded | D13: Antofagasta | E13: NH3 | F13: 2020 | G13: SOEC | H13: Parabolic50 | I13: Data_base_case | J13: Antofagasta_2020 | K13: Results_main_pre-run | L13: FALSE | M13: TRUE | N13: FALSE | O13: FALSE | P13: FALSE
A14: =ROW(A14)-ROW($A$7) -> 7 | B14: Islanded | C14: =B14 -> Islanded | D14: Antofagasta | E14: NH3 | F14: 2020 | G14: SOEC | H14: Tower100 | I14: Data_base_case | J14: Antofagasta_2020 | K14: Results_main_pre-run | L14: FALSE | M14: TRUE | N14: FALSE | O14: FALSE | P14: FALSE
A15: =ROW(A15)-ROW($A$7) -> 8 | B15: Islanded | C15: =B15 -> Islanded | D15: Antofagasta | E15: NH3 | F15: 2020 | G15: SOEC | H15: Parabolic100 | I15: Data_base_case | J15: Antofagasta_2020 | K15: Results_main_pre-run | L15: FALSE | M15: TRUE | N15: FALSE | O15: FALSE | P15: FALSE
A16: =ROW(A16)-ROW($A$7) -> 9 | B16: CSP_only | C16: =B16 -> CSP_only | D16: Antofagasta | E16: NH3 | F16: 2020 | G16: AEC | H16: Tower50 | I16: Data_base_case | J16: Antofagasta_2020 | K16: Results_main_pre-run | L16: FALSE | M16: TRUE | N16: FALSE | O16: FALSE | P16: FALSE
A17: =ROW(A17)-ROW($A$7) -> 10 | B17: CSP_only | C17: =B17 -> CSP_only | D17: Antofagasta | E17: NH3 | F17: 2020 | G17: AEC | H17: Parabolic50 | I17: Data_base_case | J17: Antofagasta_2020 | K17: Results_main_pre-run | L17: FALSE | M17: TRUE | N17: FALSE | O17: FALSE | P17: FALSE
A18: =ROW(A18)-ROW($A$7) -> 11 | B18: CSP_only | C18: =B18 -> CSP_only | D18: Antofagasta | E18: NH3 | F18: 2020 | G18: AEC | H18: Tower100 | I18: Data_base_case | J18: Antofagasta_2020 | K18: Results_main_pre-run | L18: FALSE | M18: TRUE | N18: FALSE | O18: FALSE | P18: FALSE
A19: =ROW(A19)-ROW($A$7) -> 12 | B19: CSP_only | C19: =B19 -> CSP_only | D19: Antofagasta | E19: NH3 | F19: 2020 | G19: AEC | H19: Parabolic100 | I19: Data_base_case | J19: Antofagasta_2020 | K19: Results_main_pre-run | L19: FALSE | M19: TRUE | N19: FALSE | O19: FALSE | P19: FALSE
... A23: =ROW(A23)-ROW($A$7) -> 16 | B23: CSP_only | C23: =B23 -> CSP_only | D23: Antofagasta | E23: NH3 | F23: 2020 | G23: SOEC | H23: Parabolic100 | I23: Data_base_case | J23: Antofagasta_2020 | K23: Results_main_pre-run | L23: FALSE | M23: TRUE | N23: FALSE | O23: FALSE | P23: FALSE
